Workbook

Sheet ABRs
A1: READ ME
A2: Name | B2: Strain | C2: Gender | D2: DOB | E2: Age (d.o.) | F2: Condition | G2: ABR 1 (5 days pre-n.e.) | H2: ABR 2 (Day 5 of n.e.) | I2: ABR 3 (Day 20 of n.e.) | J2: ABR 4 (Day 5 post-n.e.) | K2: ABR 5 (Day 20 post-n.e.) | L2: Age at ABR 1 | M2: Age at ABR 2 | N2: Age at ABR 3 | O2: Age at ABR 4 | P2: Age at ABR 5
A3: Rosaria | B3: C57 | C3: F | D3: 44803 | E3: =TODAY()-Table1[[#This Row],[DOB]] -> 1336 | F3: 8HRS | G3: 45104 | H3: =Table1[[#This Row],[ABR 1 (5 days pre-n.e.)]] + 10 -> 45114 | I3: =Table1[[#This Row],[ABR 2 (Day 5 of n.e.)]] + 15 -> 45129 | J3: =Table1[[#This Row],[ABR 3 (Day 20 of n.e.)]] + 25 -> 45154 | K3: =Table1[[#This Row],[ABR 4 (Day 5 post-n.e.)]] + 15 -> 45169 | L3: =Table1[[#This Row],[ABR 1 (5 days pre-n.e.)]] -Table1[[#This Row],[DOB]] -> 301 | M3: =Table1[[#This Row],[ABR 2 (Day 5 of n.e.)]] - Table1[[#This Row],[DOB]] -> 311 | N3: =Table1[[#This Row],[ABR 3 (Day 20 of n.e.)]] - Table1[[#This Row],[DOB]] -> 326 | O3: =Table1[[#This Row],[ABR 4 (Day 5 post-n.e.)]] -Table1[[#This Row],[DOB]] -> 351 | P3: =Table1[[#This Row],[ABR 5 (Day 20 post-n.e.)]] -Table1[[#This Row],[DOB]] -> 366
A4: Irina | B4: C57 | C4: F | D4: 44803 | E4: =TODAY()-Table1[[#This Row],[DOB]] -> 1336 | F4: 8HRS | G4: 45104 | H4: =Table1[[#This Row],[ABR 1 (5 days pre-n.e.)]] + 10 -> 45114 | I4: =Table1[[#This Row],[ABR 2 (Day 5 of n.e.)]] + 15 -> 45129 | J4: =Table1[[#This Row],[ABR 3 (Day 20 of n.e.)]] + 25 -> 45154 | K4: =Table1[[#This Row],[ABR 4 (Day 5 post-n.e.)]] + 15 -> 45169 | L4: =Table1[[#This Row],[ABR 1 (5 days pre-n.e.)]] -Table1[[#This Row],[DOB]] -> 301 | M4: =Table1[[#This Row],[ABR 2 (Day 5 of n.e.)]] - Table1[[#This Row],[DOB]] -> 311 | N4: =Table1[[#This Row],[ABR 3 (Day 20 of n.e.)]] - Table1[[#This Row],[DOB]] -> 326 | O4: =Table1[[#This Row],[ABR 4 (Day 5 post-n.e.)]] -Table1[[#This Row],[DOB]] -> 351 | P4: =Table1[[#This Row],[ABR 5 (Day 20 post-n.e.)]] -Table1[[#This Row],[DOB]] -> 366
A5: Quelaag | B5: C57 | C5: F | D5: 44803 | E5: =TODAY()-Table1[[#This Row],[DOB]] -> 1336 | F5: 8HRS | G5: 45108 | H5: =Table1[[#This Row],[ABR 1 (5 days pre-n.e.)]] + 10 -> 45118 | I5: =Table1[[#This Row],[ABR 2 (Day 5 of n.e.)]] + 15 -> 45133 | J5: =Table1[[#This Row],[ABR 3 (Day 20 of n.e.)]] + 25 -> 45158 | K5: =Table1[[#This Row],[ABR 4 (Day 5 post-n.e.)]] + 15 -> 45173 | L5: =Table1[[#This Row],[ABR 1 (5 days pre-n.e.)]] -Table1[[#This Row],[DOB]] -> 305 | M5: =Table1[[#This Row],[ABR 2 (Day 5 of n.e.)]] - Table1[[#This Row],[DOB]] -> 315 | N5: =Table1[[#This Row],[ABR 3 (Day 20 of n.e.)]] - Table1[[#This Row],[DOB]] -> 330 | O5: =Table1[[#This Row],[ABR 4 (Day 5 post-n.e.)]] -Table1[[#This Row],[DOB]] -> 355 | P5: =Table1[[#This Row],[ABR 5 (Day 20 post-n.e.)]] -Table1[[#This Row],[DOB]] -> 370
A6: Artorias | B6: C57 | C6: M | D6: 44803 | E6: =TODAY()-Table1[[#This Row],[DOB]] -> 1336 | F6: 8HRS | G6: 45114 | H6: =Table1[[#This Row],[ABR 1 (5 days pre-n.e.)]] + 10 -> 45124 | I6: =Table1[[#This Row],[ABR 2 (Day 5 of n.e.)]] + 15 -> 45139 | J6: =Table1[[#This Row],[ABR 3 (Day 20 of n.e.)]] + 25 -> 45164 | K6: =Table1[[#This Row],[ABR 4 (Day 5 post-n.e.)]] + 15 -> 45179 | L6: =Table1[[#This Row],[ABR 1 (5 days pre-n.e.)]] -Table1[[#This Row],[DOB]] -> 311 | M6: =Table1[[#This Row],[ABR 2 (Day 5 of n.e.)]] - Table1[[#This Row],[DOB]] -> 321 | N6: =Table1[[#This Row],[ABR 3 (Day 20 of n.e.)]] - Table1[[#This Row],[DOB]] -> 336 | O6: =Table1[[#This Row],[ABR 4 (Day 5 post-n.e.)]] -Table1[[#This Row],[DOB]] -> 361 | P6: =Table1[[#This Row],[ABR 5 (Day 20 post-n.e.)]] -Table1[[#This Row],[DOB]] -> 376
A7: Sif | B7: C57 | C7: M | D7: 44803 | E7: =TODAY()-Table1[[#This Row],[DOB]] -> 1336 | F7: 8HRS | G7: 45114 | H7: =Table1[[#This Row],[ABR 1 (5 days pre-n.e.)]] + 10 -> 45124 | I7: =Table1[[#This Row],[ABR 2 (Day 5 of n.e.)]] + 15 -> 45139 | J7: =Table1[[#This Row],[ABR 3 (Day 20 of n.e.)]] + 25 -> 45164 | K7: =Table1[[#This Row],[ABR 4 (Day 5 post-n.e.)]] + 15 -> 45179 | L7: =Table1[[#This Row],[ABR 1 (5 days pre-n.e.)]] -Table1[[#This Row],[DOB]] -> 311 | M7: =Table1[[#This Row],[ABR 2 (Day 5 of n.e.)]] - Table1[[#This Row],[DOB]] -> 321 | N7: =Table1[[#This Row],[ABR 3 (Day 20 of n.e.)]] - Table1[[#This Row],[DOB]] -> 336 | O7: =Table1[[#This Row],[ABR 4 (Day 5 post-n.e.)]] -Table1[[#This Row],[DOB]] -> 361 | P7: =Table1[[#This Row],[ABR 5 (Day 20 post-n.e.)]] -Table1[[#This Row],[DOB]] -> 376
A8: Eygon | B8: C57 | C8: M | D8: 44803 | E8: =TODAY()-Table1[[#This Row],[DOB]] -> 1336 | F8: 8HRS | G8: 45114 | H8: =Table1[[#This Row],[ABR 1 (5 days pre-n.e.)]] + 10 -> 45124 | I8: =Table1[[#This Row],[ABR 2 (Day 5 of n.e.)]] + 15 -> 45139 | J8: =Table1[[#This Row],[ABR 3 (Day 20 of n.e.)]] + 25 -> 45164 | K8: =Table1[[#This Row],[ABR 4 (Day 5 post-n.e.)]] + 15 -> 45179 | L8: =Table1[[#This Row],[ABR 1 (5 days pre-n.e.)]] -Table1[[#This Row],[DOB]] -> 311 | M8: =Table1[[#This Row],[ABR 2 (Day 5 of n.e.)]] - Table1[[#This Row],[DOB]] -> 321 | N8: =Table1[[#This Row],[ABR 3 (Day 20 of n.e.)]] - Table1[[#This Row],[DOB]] -> 336 | O8: =Table1[[#This Row],[ABR 4 (Day 5 post-n.e.)]] -Table1[[#This Row],[DOB]] -> 361 | P8: =Table1[[#This Row],[ABR 5 (Day 20 post-n.e.)]] -Table1[[#This Row],[DOB]] -> 376
A9: Velka | B9: C57 | C9: F | D9: 44817 | E9: =TODAY()-Table1[[#This Row],[DOB]] -> 1322 | F9: 23HRS | G9: 45120 | H9: =Table1[[#This Row],[ABR 1 (5 days pre-n.e.)]] + 10 -> 45130 | I9: =Table1[[#This Row],[ABR 2 (Day 5 of n.e.)]] + 15 -> 45145 | J9: =Table1[[#This Row],[ABR 3 (Day 20 of n.e.)]] + 25 -> 45170 | K9: =Table1[[#This Row],[ABR 4 (Day 5 post-n.e.)]] + 15 -> 45185 | L9: =Table1[[#This Row],[ABR 1 (5 days pre-n.e.)]] -Table1[[#This Row],[DOB]] -> 303 | M9: =Table1[[#This Row],[ABR 2 (Day 5 of n.e.)]] - Table1[[#This Row],[DOB]] -> 313 | N9: =Table1[[#This Row],[ABR 3 (Day 20 of n.e.)]] - Table1[[#This Row],[DOB]] -> 328 | O9: =Table1[[#This Row],[ABR 4 (Day 5 post-n.e.)]] -Table1[[#This Row],[DOB]] -> 353 | P9: =Table1[[#This Row],[ABR 5 (Day 20 post-n.e.)]] -Table1[[#This Row],[DOB]] -> 368
A10: Alsanna | B10: C57 | C10: F | D10: 44817 | E10: =TODAY()-Table1[[#This Row],[DOB]] -> 1322 | F10: 23HRS | G10: 45120 | H10: =Table1[[#This Row],[ABR 1 (5 days pre-n.e.)]] + 10 -> 45130 | I10: =Table1[[#This Row],[ABR 2 (Day 5 of n.e.)]] + 15 -> 45145 | J10: =Table1[[#This Row],[ABR 3 (Day 20 of n.e.)]] + 25 -> 45170 | K10: =Table1[[#This Row],[ABR 4 (Day 5 post-n.e.)]] + 15 -> 45185 | L10: =Table1[[#This Row],[ABR 1 (5 days pre-n.e.)]] -Table1[[#This Row],[DOB]] -> 303 | M10: =Table1[[#This Row],[ABR 2 (Day 5 of n.e.)]] - Table1[[#This Row],[DOB]] -> 313 | N10: =Table1[[#This Row],[ABR 3 (Day 20 of n.e.)]] - Table1[[#This Row],[DOB]] -> 328 | O10: =Table1[[#This Row],[ABR 4 (Day 5 post-n.e.)]] -Table1[[#This Row],[DOB]] -> 353 | P10: =Table1[[#This Row],[ABR 5 (Day 20 post-n.e.)]] -Table1[[#This Row],[DOB]] -> 368
A11: Nashandra | B11: C57 | C11: F | D11: 44817 | E11: =TODAY()-Table1[[#This Row],[DOB]] -> 1322 | F11: 23HRS | G11: 45120 | H11: =Table1[[#This Row],[ABR 1 (5 days pre-n.e.)]] + 10 -> 45130 | I11: =Table1[[#This Row],[ABR 2 (Day 5 of n.e.)]] + 15 -> 45145 | J11: =Table1[[#This Row],[ABR 3 (Day 20 of n.e.)]] + 25 -> 45170 | K11: =Table1[[#This Row],[ABR 4 (Day 5 post-n.e.)]] + 15 -> 45185 | L11: =Table1[[#This Row],[ABR 1 (5 days pre-n.e.)]] -Table1[[#This Row],[DOB]] -> 303 | M11: =Table1[[#This Row],[ABR 2 (Day 5 of n.e.)]] - Table1[[#This Row],[DOB]] -> 313 | N11: =Table1[[#This Row],[ABR 3 (Day 20 of n.e.)]] - Table1[[#This Row],[DOB]] -> 328 | O11: =Table1[[#This Row],[ABR 4 (Day 5 post-n.e.)]] -Table1[[#This Row],[DOB]] -> 353 | P11: =Table1[[#This Row],[ABR 5 (Day 20 post-n.e.)]] -Table1[[#This Row],[DOB]] -> 368
A12: Patches | B12: C57 | C12: M | D12: 44817 | E12: =TODAY()-Table1[[#This Row],[DOB]] -> 1322 | F12: 23HRS | G12: 45128 | H12: =Table1[[#This Row],[ABR 1 (5 days pre-n.e.)]] + 10 -> 45138 | I12: =Table1[[#This Row],[ABR 2 (Day 5 of n.e.)]] + 15 -> 45153 | J12: =Table1[[#This Row],[ABR 3 (Day 20 of n.e.)]] + 25 -> 45178 | K12: =Table1[[#This Row],[ABR 4 (Day 5 post-n.e.)]] + 15 -> 45193 | L12: =Table1[[#This Row],[ABR 1 (5 days pre-n.e.)]] -Table1[[#This Row],[DOB]] -> 311 | M12: =Table1[[#This Row],[ABR 2 (Day 5 of n.e.)]] - Table1[[#This Row],[DOB]] -> 321 | N12: =Table1[[#This Row],[ABR 3 (Day 20 of n.e.)]] - Table1[[#This Row],[DOB]] -> 336 | O12: =Table1[[#This Row],[ABR 4 (Day 5 post-n.e.)]] -Table1[[#This Row],[DOB]] -> 361 | P12: =Table1[[#This Row],[ABR 5 (Day 20 post-n.e.)]] -Table1[[#This Row],[DOB]] -> 376
A13: Hawkwood | B13: C57 | C13: M | D13: 44817 | E13: =TODAY()-Table1[[#This Row],[DOB]] -> 1322 | F13: 23HRS | G13: 45128 | H13: =Table1[[#This Row],[ABR 1 (5 days pre-n.e.)]] + 10 -> 45138 | I13: =Table1[[#This Row],[ABR 2 (Day 5 of n.e.)]] + 15 -> 45153 | J13: =Table1[[#This Row],[ABR 3 (Day 20 of n.e.)]] + 25 -> 45178 | K13: =Table1[[#This Row],[ABR 4 (Day 5 post-n.e.)]] + 15 -> 45193 | L13: =Table1[[#This Row],[ABR 1 (5 days pre-n.e.)]] -Table1[[#This Row],[DOB]] -> 311 | M13: =Table1[[#This Row],[ABR 2 (Day 5 of n.e.)]] - Table1[[#This Row],[DOB]] -> 321 | N13: =Table1[[#This Row],[ABR 3 (Day 20 of n.e.)]] - Table1[[#This Row],[DOB]] -> 336 | O13: =Table1[[#This Row],[ABR 4 (Day 5 post-n.e.)]] -Table1[[#This Row],[DOB]] -> 361 | P13: =Table1[[#This Row],[ABR 5 (Day 20 post-n.e.)]] -Table1[[#This Row],[DOB]] -> 376
A14: Kalameet | B14: C57 | C14: M | D14: 44817 | E14: =TODAY()-Table1[[#This Row],[DOB]] -> 1322 | F14: 23HRS | G14: 45132 | H14: =Table1[[#This Row],[ABR 1 (5 days pre-n.e.)]] + 10 -> 45142 | I14: =Table1[[#This Row],[ABR 2 (Day 5 of n.e.)]] + 15 -> 45157 | J14: =Table1[[#This Row],[ABR 3 (Day 20 of n.e.)]] + 25 -> 45182 | K14: =Table1[[#This Row],[ABR 4 (Day 5 post-n.e.)]] + 15 -> 45197 | L14: =Table1[[#This Row],[ABR 1 (5 days pre-n.e.)]] -Table1[[#This Row],[DOB]] -> 315 | M14: =Table1[[#This Row],[ABR 2 (Day 5 of n.e.)]] - Table1[[#This Row],[DOB]] -> 325 | N14: =Table1[[#This Row],[ABR 3 (Day 20 of n.e.)]] - Table1[[#This Row],[DOB]] -> 340 | O14: =Table1[[#This Row],[ABR 4 (Day 5 post-n.e.)]] -Table1[[#This Row],[DOB]] -> 365 | P14: =Table1[[#This Row],[ABR 5 (Day 20 post-n.e.)]] -Table1[[#This Row],[DOB]] -> 380
... A30: Clarke | B30: C57 | C30: M | D30: 44871 | E30: =TODAY()-Table1[[#This Row],[DOB]] -> 1268 | F30: 8HRS | G30: 45225 | H30: =Table1[[#This Row],[ABR 1 (5 days pre-n.e.)]] + 10 -> 45235 | I30: =Table1[[#This Row],[ABR 2 (Day 5 of n.e.)]] + 15 -> 45250 | J30: =Table1[[#This Row],[ABR 3 (Day 20 of n.e.)]] + 25 -> 45275 | K30: =Table1[[#This Row],[ABR 4 (Day 5 post-n.e.)]] + 15 -> 45290 | L30: =Table1[[#This Row],[ABR 1 (5 days pre-n.e.)]] -Table1[[#This Row],[DOB]] -> 354 | M30: =Table1[[#This Row],[ABR 2 (Day 5 of n.e.)]] - Table1[[#This Row],[DOB]] -> 364 | N30: =Table1[[#This Row],[ABR 3 (Day 20 of n.e.)]] - Table1[[#This Row],[DOB]] -> 379 | O30: =Table1[[#This Row],[ABR 4 (Day 5 post-n.e.)]] -Table1[[#This Row],[DOB]] -> 404 | P30: =Table1[[#This Row],[ABR 5 (Day 20 post-n.e.)]] -Table1[[#This Row],[DOB]] -> 419

Sheet Noise Exposure Schedule
A1: Name | B1: Strain | C1: Gender | D1: DOB | E1: Age (d.o.) | F1: Condition | G1: NE Start | H1: NE End | I1: Booth
A2: Rosaria | B2: C57 | C2: F | D2: 44803 | E2: =TODAY() - Table4[[#This Row],[DOB]] -> 1336 | F2: 8HRs | G2: =ABRs!G3 + 5 -> 45109 | H2: =Table4[[#This Row],[NE Start]] + 40 -> 45149 | I2: 1.1
A3: Irina | B3: C57 | C3: F | D3: 44803 | E3: =TODAY() - Table4[[#This Row],[DOB]] -> 1336 | F3: 8HRs | G3: =ABRs!G4 + 5 -> 45109 | H3: =Table4[[#This Row],[NE Start]] + 40 -> 45149 | I3: 1.1
A4: Quelaag | B4: C57 | C4: F | D4: 44803 | E4: =TODAY() - Table4[[#This Row],[DOB]] -> 1336 | F4: 8HRs | G4: =ABRs!G5 + 5 -> 45113 | H4: =Table4[[#This Row],[NE Start]] + 40 -> 45153 | I4: 1.1
A5: Artorias | B5: C57 | C5: M | D5: 44803 | E5: =TODAY() - Table4[[#This Row],[DOB]] -> 1336 | F5: 8HRs | G5: =ABRs!G6 + 5 -> 45119 | H5: =Table4[[#This Row],[NE Start]] + 40 -> 45159 | I5: 1.2
A6: Sif | B6: C57 | C6: M | D6: 44803 | E6: =TODAY() - Table4[[#This Row],[DOB]] -> 1336 | F6: 8HRs | G6: =ABRs!G7 + 5 -> 45119 | H6: =Table4[[#This Row],[NE Start]] + 40 -> 45159 | I6: 2.1
A7: Eygon | B7: C57 | C7: M | D7: 44803 | E7: =TODAY() - Table4[[#This Row],[DOB]] -> 1336 | F7: 8HRs | G7: =ABRs!G8 + 5 -> 45119 | H7: =Table4[[#This Row],[NE Start]] + 40 -> 45159 | I7: 1.2
A8: Velka | B8: C57 | C8: F | D8: 44817 | E8: =TODAY() - Table4[[#This Row],[DOB]] -> 1322 | F8: 23HRs | G8: =ABRs!G9 + 5 -> 45125 | H8: =Table4[[#This Row],[NE Start]] + 40 -> 45165 | I8: 4.1
A9: Alsanna | B9: C57 | C9: F | D9: 44817 | E9: =TODAY() - Table4[[#This Row],[DOB]] -> 1322 | F9: 23HRs | G9: =ABRs!G10 + 5 -> 45125 | H9: =Table4[[#This Row],[NE Start]] + 40 -> 45165 | I9: 4.1
A10: Nashandra | B10: C57 | C10: F | D10: 44817 | E10: =TODAY() - Table4[[#This Row],[DOB]] -> 1322 | F10: 23HRs | G10: =ABRs!G11 + 5 -> 45125 | H10: =Table4[[#This Row],[NE Start]] + 40 -> 45165 | I10: 4.1
A11: Patches | B11: C57 | C11: M | D11: 44817 | E11: =TODAY() - Table4[[#This Row],[DOB]] -> 1322 | F11: 23HRs | G11: =ABRs!G12 + 5 -> 45133 | H11: =Table4[[#This Row],[NE Start]] + 40 -> 45173 | I11: 4.2
A12: Hawkwood | B12: C57 | C12: M | D12: 44817 | E12: =TODAY() - Table4[[#This Row],[DOB]] -> 1322 | F12: 23HRs | G12: =ABRs!G13 + 5 -> 45133 | H12: =Table4[[#This Row],[NE Start]] + 40 -> 45173 | I12: 4.2
A13: Kalameet | B13: C57 | C13: M | D13: 44817 | E13: =TODAY() - Table4[[#This Row],[DOB]] -> 1322 | F13: 23HRs | G13: =ABRs!G14 + 5 -> 45137 | H13: =Table4[[#This Row],[NE Start]] + 40 -> 45177 | I13: 4.2
... A29: Clarke | B29: C57 | C29: M | D29: 44871 | E29: =TODAY() - Table4[[#This Row],[DOB]] -> 1268 | F29: 8HRs | G29: =ABRs!G30 + 5 -> 45230 | H29: =Table4[[#This Row],[NE Start]] + 40 -> 45270 | I29: 2.1

Sheet ABR Raw Data
A1: SGI | B1: Rec No. | C1: Gain | D1: No. Avgs | E1: No. Arts | F1: Time | G1: Chan | H1: Sub. ID | I1: Sub. Ref-1 | J1: Sub. Ref-2 | K1: Sub. Memo | M1: Freq(Hz) | N1: Level(dB) | O1: Atten-A(dB) | P1: Phase(deg) | Q1: Duration(ms) | R1: GateTime(ms) | S1: Samp. Per. | T1: No. Samps. | U1: O.S. Time | V1: Data(nv)... | W1: 0 | X1: 1 | Y1: 2 | Z1: 3 | AA1: 4 | AB1: 5 | AC1: 6 | AD1: 7 | AE1: 8 | AF1: 9 | AG1: 10 | AH1: 11 | AI1: 12 | AJ1: 13 | AK1: 14 | AL1: 15 | AM1: 16 | AN1: 17 | AO1: 18 | AP1: 19 | AQ1: 20 | AR1: 21 | AS1: 22 | AT1: 23 | AU1: 24 | AV1: 25 | AW1: 26 | AX1: 27 | AY1: 28 | AZ1: 29 | BA1: 30 | BB1: 31 | BC1: 32 | BD1: 33 | BE1: 34 | BF1: 35 | BG1: 36 | BH1: 37 | BI1: 38 | BJ1: 39 | BK1: 40 | BL1: 41 | BM1: 42 | BN1: 43 | BO1: 44 | BP1: 45 | BQ1: 46 | BR1: 47 | BS1: 48 | BT1: 49 | BU1: 50 | BV1: 51 | BW1: 52 | BX1: 53 | BY1: 54 | BZ1: 55 | CA1: 56 | CB1: 57 | CC1: 58 | CD1: 59 | CE1: 60 | CF1: 61 | CG1: 62 | CH1: 63 | CI1: 64 | CJ1: 65 | CK1: 66 | CL1: 67 | CM1: 68 | CN1: 69 | CO1: 70 | CP1: 71 | CQ1: 72 | CR1: 73 | CS1: 74 | CT1: 75 | CU1: 76 | CV1: 77 | CW1: 78 | CX1: 79 | CY1: 80 | CZ1: 81 | DA1: 82 | DB1: 83 | DC1: 84 | DD1: 85 | DE1: 86 | DF1: 87 | DG1: 88 | DH1: 89 | DI1: 90 | DJ1: 91 | DK1: 92 | DL1: 93 | DM1: 94 | DN1: 95 | DO1: 96 | DP1: 97 | DQ1: 98 | DR1: 99 | DS1: 100 | DT1: 101 | DU1: 102 | DV1: 103 | DW1: 104 | DX1: 105 | DY1: 106 | DZ1: 107 | EA1: 108 | EB1: 109 | EC1: 110 | ED1: 111 | EE1: 112 | EF1: 113 | EG1: 114 | EH1: 115 | EI1: 116 | EJ1: 117 | EK1: 118 | EL1: 119 | EM1: 120 | EN1: 121 | EO1: 122 | EP1: 123 | EQ1: 124 | ER1: 125 | ES1: 126 | ET1: 127 | EU1: 128 | EV1: 129 | EW1: 130 | EX1: 131 | EY1: 132 | EZ1: 133 | FA1: 134 | FB1: 135 | FC1: 136 | FD1: 137 | FE1: 138 | FF1: 139 | FG1: 140 | FH1: 141 | FI1: 142 | FJ1: 143 | FK1: 144 | FL1: 145 | FM1: 146 | FN1: 147 | FO1: 148 | FP1: 149 | FQ1: 150 | FR1: 151 | FS1: 152 | FT1: 153 | FU1: 154 | FV1: 155 | FW1: 156 | FX1: 157 | FY1: 158 | FZ1: 159 | GA1: 160 | GB1: 161 | GC1: 162 | GD1: 163 | GE1: 164 | GF1: 165 | GG1: 166 | GH1: 167 | GI1: 168 | GJ1: 169 | GK1: 170 | GL1: 171 | GM1: 172 | GN1: 173 | GO1: 174 | GP1: 175 | GQ1: 176 | GR1: 177 | GS1: 178 | GT1: 179 | GU1: 180 | GV1: 181 | GW1: 182 | GX1: 183 | GY1: 184 | GZ1: 185 | HA1: 186 | HB1: 187 | HC1: 188 | HD1: 189 | HE1: 190 | HF1: 191 | HG1: 192 | HH1: 193 | HI1: 194 | HJ1: 195 | HK1: 196 | HL1: 197 | HM1: 198 | HN1: 199 | HO1: 200 | HP1: 201 | HQ1: 202 | HR1: 203 | HS1: 204 | HT1: 205 | HU1: 206 | HV1: 207 | HW1: 208 | HX1: 209 | HY1: 210 | HZ1: 211 | IA1: 212 | IB1: 213 | IC1: 214 | ID1: 215 | IE1: 216 | IF1: 217 | IG1: 218 | IH1: 219 | II1: 220 | IJ1: 221 | IK1: 222 | IL1: 223 | IM1: 224 | IN1: 225 | IO1: 226 | IP1: 227 | IQ1: 228 | IR1: 229 | IS1: 230 | IT1: 231 | IU1: 232 | IV1: 233 | IW1: 234 | IX1: 235 | IY1: 236 | IZ1: 237 | JA1: 238 | JB1: 239 | JC1: 240 | JD1: 241 | JE1: 242 | JF1: 243
A2: 1 | B2: 28 | C2: 1 | D2: 512 | E2: 0 | F2: 1691417405 | G2: 1 | H2: Alsanna | K2: ABR 3 left ear | M2: 4000 | N2: 90 | O2: 0 | P2: 90 | Q2: 5 | R2: 2 | S2: 40.96 | T2: 244 | U2: 0 | W2: 109.959 | X2: 137.104 | Y2: 153.895 | Z2: 157.268 | AA2: 147.905 | AB2: 129.085 | AC2: 104.877 | AD2: 78.855 | AE2: 53.709 | AF2: 31.411 | AG2: 13.33 | AH2: 0.098 | AI2: -8.596 | AJ2: -13.976 | AK2: -17.825 | AL2: -21.955 | AM2: -27.743 | AN2: -35.851 | AO2: -46.169 | AP2: -57.922 | AQ2: -69.901 | AR2: -80.733 | AS2: -89.136 | AT2: -94.139 | AU2: -95.266 | AV2: -92.652 | AW2: -86.994 | AX2: -79.34 | AY2: -70.846 | AZ2: -62.688 | BA2: -56.103 | BB2: -52.293 | BC2: -52.027 | BD2: -55.096 | BE2: -59.927 | BF2: -63.651 | BG2: -62.782 | BH2: -54.472 | BI2: -38.013 | BJ2: -15.726 | BK2: 7.579 | BL2: 26.678 | BM2: 38.564 | BN2: 44.06 | BO2: 47.33 | BP2: 53.315 | BQ2: 64.429 | BR2: 78.503 | BS2: 89.524 | BT2: 91.018 | BU2: 80.096 | BV2: 59.46 | BW2: 35.943 | BX2: 16.582 | BY2: 4.967 | BZ2: 0.245 | CA2: -0.975 | CB2: -1.639 | CC2: -2.529 | CD2: -2.729 | CE2: -1.422 | CF2: 0.741 | CG2: 1.729 | CH2: -0.601 | CI2: -7.261 | CJ2: -17.804 | CK2: -30.778 | CL2: -44.291 | CM2: -56.262 | CN2: -64.641 | CO2: -67.888 | CP2: -65.501 | CQ2: -58.153 | CR2: -47.344 | CS2: -34.955 | CT2: -22.914 | CU2: -12.873 | CV2: -5.642 | CW2: -0.509 | CX2: 5.023 | CY2: 14.456 | CZ2: 30.467 | DA2: 53.006 | DB2: 78.76 | DC2: 102.596 | DD2: 120.052 | DE2: 129.108 | DF2: 130.154 | DG2: 124.68 | DH2: 114.047 | DI2: 99.279 | DJ2: 81.585 | DK2: 62.721 | DL2: 44.671 | DM2: 28.989 | DN2: 16.45 | DO2: 7.197 | DP2: 1.007 | DQ2: -2.733 | DR2: -5.299 | DS2: -8.739 | DT2: -15.387 | DU2: -26.73 | DV2: -42.187 | DW2: -58.698 | DX2: -71.789 | DY2: -77.768 | DZ2: -75.81 | EA2: -68.555 | EB2: -60.727 | EC2: -56.619 | ED2: -57.98 | EE2: -63.587 | EF2: -70.591 | EG2: -76.471 | EH2: -80.153 | EI2: -81.685 | EJ2: -81.186 | EK2: -78.231 | EL2: -72.144 | EM2: -62.703 | EN2: -50.531 | EO2: -36.978 | EP2: -23.762 | EQ2: -12.528 | ER2: -4.277 | ES2: 1.26 | ET2: 5.859 | EU2: 12.211 | EV2: 22.63 | EW2: 37.769 | EX2: 56.102 | EY2: 74.382 | EZ2: 88.754 | FA2: 95.942 | FB2: 94.097 | FC2: 83.196 | FD2: 65.1 | FE2: 43.357 | FF2: 22.614 | FG2: 7.411 | FH2: 0.518 | FI2: 1.564 | FJ2: 6.934 | FK2: 11.371 | FL2: 10.611 | FM2: 3.669 | FN2: -6.564 | FO2: -14.863 | FP2: -16.627 | FQ2: -10.571 | FR2: 0.472 | FS2: 11.203 | FT2: 16.858 | FU2: 15.668 | FV2: 9.346 | FW2: 1.568 | FX2: -4.312 | FY2: -6.89 | FZ2: -6.964 | GA2: -6.683 | GB2: -8.34 | GC2: -13.327 | GD2: -21.431 | GE2: -30.601 | GF2: -37.373 | GG2: -38.043 | GH2: -30.292 | GI2: -14.555 | GJ2: 5.718 | GK2: 25.294 | GL2: 39.358 | GM2: 45.52 | GN2: 44.538 | GO2: 39.47 | GP2: 33.812 | GQ2: 29.65 | GR2: 26.799 | GS2: 23.418 | GT2: 17.672 | GU2: 9.303 | GV2: -0.061 | GW2: -7.964 | GX2: -12.591 | GY2: -13.498 | GZ2: -11.327 | HA2: -7.207 | HB2: -2.522 | HC2: 0.943 | HD2: 1.125 | HE2: -3.506 | HF2: -12.804 | HG2: -24.374 | HH2: -34.285 | HI2: -38.916 | HJ2: -36.874 | HK2: -29.775 | HL2: -21.352 | HM2: -15.507 | HN2: -14.506 | HO2: -18.216 | HP2: -24.465 | HQ2: -30.075 | HR2: -32.075 | HS2: -28.695 | HT2: -19.844 | HU2: -6.949 | HV2: 7.658 | HW2: 21.506 | HX2: 32.599 | HY2: 39.716 | HZ2: 42.3 | IA2: 40.169 | IB2: 33.407 | IC2: 22.715 | ID2: 9.871 | IE2: -2.293 | IF2: -10.767 | IG2: -13.686 | IH2: -11.325 | II2: -6.084 | IJ2: -1.374 | IK2: 0.072 | IL2: -2.392 | IM2: -6.974 | IN2: -10.346 | IO2: -9.351 | IP2: -2.592 | IQ2: 8.93 | IR2: 22.372 | IS2: 34.28 | IT2: 41.562 | IU2: 41.749 | IV2: 32.959 | IW2: 14.494 | IX2: -11.665 | IY2: -39.447 | IZ2: -59.263 | JA2: -61.777 | JB2: -43.793 | JC2: -12.397 | JD2: 17.376 | JE2: 32.617 | JF2: 32.015
A3: 2 | B3: 29 | C3: 1 | D3: 512 | E3: 0 | F3: 1691417430 | G3: 1 | H3: Alsanna | K3: ABR 3 left ear | M3: 4000 | N3: 80 | O3: 10 | P3: 90 | Q3: 5 | R3: 2 | S3: 40.96 | T3: 244 | U3: 0 | W3: 79.851 | X3: 120.839 | Y3: 138.749 | Z3: 131.212 | AA3: 105.043 | AB3: 72.093 | AC3: 43.479 | AD3: 25.184 | AE3: 16.793 | AF3: 13.381 | AG3: 9.127 | AH3: 0.597 | AI3: -11.955 | AJ3: -25.553 | AK3: -36.763 | AL3: -43.607 | AM3: -46.038 | AN3: -45.035 | AO3: -41.407 | AP3: -35.315 | AQ3: -26.628 | AR3: -15.505 | AS3: -2.661 | AT3: 10.681 | AU3: 22.918 | AV3: 32.251 | AW3: 37.078 | AX3: 36.615 | AY3: 31.489 | AZ3: 23.877 | BA3: 16.955 | BB3: 13.72 | BC3: 15.66 | BD3: 21.883 | BE3: 29.251 | BF3: 33.702 | BG3: 32.314 | BH3: 25.031 | BI3: 14.954 | BJ3: 6.858 | BK3: 4.701 | BL3: 9.481 | BM3: 18.688 | BN3: 27.66 | BO3: 32.075 | BP3: 30.043 | BQ3: 22.584 | BR3: 12.424 | BS3: 2.128 | BT3: -7.131 | BU3: -15.5 | BV3: -23.438 | BW3: -30.777 | BX3: -36.636 | BY3: -40.094 | BZ3: -40.842 | CA3: -39.303 | CB3: -36.35 | CC3: -33.138 | CD3: -31.097 | CE3: -31.7 | CF3: -35.759 | CG3: -42.677 | CH3: -50.359 | CI3: -56.042 | CJ3: -57.541 | CK3: -54.134 | CL3: -46.603 | CM3: -36.517 | CN3: -25.302 | CO3: -13.725 | CP3: -2.099 | CQ3: 9.063 | CR3: 18.532 | CS3: 24.532 | CT3: 25.632 | CU3: 21.847 | CV3: 15.169 | CW3: 9.041 | CX3: 6.977 | CY3: 11.031 | CZ3: 20.856 | DA3: 33.727 | DB3: 45.551 | DC3: 52.555 | DD3: 52.939 | DE3: 47.646 | DF3: 39.814 | DG3: 33.202 | DH3: 30.545 | DI3: 32.614 | DJ3: 38.124 | DK3: 44.276 | DL3: 47.738 | DM3: 45.977 | DN3: 38.434 | DO3: 26.734 | DP3: 13.617 | DQ3: 1.324 | DR3: -9.336 | DS3: -18.671 | DT3: -27.154 | DU3: -34.767 | DV3: -41.048 | DW3: -45.491 | DX3: -47.74 | DY3: -47.458 | DZ3: -44.175 | EA3: -37.458 | EB3: -27.436 | EC3: -15.406 | ED3: -4.028 | EE3: 3.289 | EF3: 3.801 | EG3: -3.003 | EH3: -14.649 | EI3: -26.392 | EJ3: -33.223 | EK3: -32.266 | EL3: -24.333 | EM3: -13.743 | EN3: -6.383 | EO3: -6.934 | EP3: -16.605 | EQ3: -32.391 | ER3: -48.168 | ES3: -57.213 | ET3: -55.106 | EU3: -41.665 | EV3: -20.922 | EW3: 0.903 | EX3: 18.363 | EY3: 29.096 | EZ3: 34.309 | FA3: 37.416 | FB3: 41.849 | FC3: 49.354 | FD3: 59.489 | FE3: 70.224 | FF3: 79.038 | FG3: 83.929 | FH3: 84.036 | FI3: 79.793 | FJ3: 72.688 | FK3: 64.706 | FL3: 57.57 | FM3: 51.961 | FN3: 47.012 | FO3: 40.498 | FP3: 29.956 | FQ3: 14.388 | FR3: -4.51 | FS3: -22.813 | FT3: -36.688 | FU3: -45.053 | FV3: -50.366 | FW3: -56.7 | FX3: -66.576 | FY3: -79.141 | FZ3: -91.081 | GA3: -99.228 | GB3: -102.514 | GC3: -101.716 | GD3: -97.561 | GE3: -89.153 | GF3: -74.295 | GG3: -51.482 | GH3: -21.919 | GI3: 10.066 | GJ3: 38.498 | GK3: 58.086 | GL3: 66.03 | GM3: 62.629 | GN3: 50.872 | GO3: 35.502 | GP3: 21.827 | GQ3: 14.339 | GR3: 15.35 | GS3: 24.109 | GT3: 36.946 | GU3: 48.566 | GV3: 54.045 | GW3: 50.642 | GX3: 38.628 | GY3: 20.88 | GZ3: 1.582 | HA3: -15.251 | HB3: -26.848 | HC3: -32.13 | HD3: -31.679 | HE3: -27.373 | HF3: -21.734 | HG3: -17.045 | HH3: -14.555 | HI3: -14.139 | HJ3: -14.562 | HK3: -14.109 | HL3: -11.223 | HM3: -4.956 | HN3: 4.734 | HO3: 16.83 | HP3: 29.306 | HQ3: 39.505 | HR3: 44.784 | HS3: 43.243 | HT3: 34.299 | HU3: 19.005 | HV3: 0.069 | HW3: -18.553 | HX3: -32.572 | HY3: -38.667 | HZ3: -35.741 | IA3: -25.553 | IB3: -12.284 | IC3: -0.977 | ID3: 4.58 | IE3: 3.443 | IF3: -2.291 | IG3: -8.75 | IH3: -12.208 | II3: -10.669 | IJ3: -4.45 | IK3: 4.266 | IL3: 12.557 | IM3: 18.054 | IN3: 19.888 | IO3: 18.8 | IP3: 16.261 | IQ3: 13.123 | IR3: 8.866 | IS3: 2.203 | IT3: -7.321 | IU3: -17.999 | IV3: -26.099 | IW3: -27.658 | IX3: -20.932 | IY3: -8.027 | IZ3: 5.571 | JA3: 13.757 | JB3: 13.514 | JC3: 7.101 | JD3: 0.693 | JE3: -0.302 | JF3: 4.794
A4: 3 | B4: 30 | C4: 1 | D4: 512 | E4: 0 | F4: 1691417455 | G4: 1 | H4: Alsanna | K4: ABR 3 left ear | M4: 4000 | N4: 70 | O4: 20 | P4: 90 | Q4: 5 | R4: 2 | S4: 40.96 | T4: 244 | U4: 0 | W4: -2.554 | X4: -20.994 | Y4: -37.6 | Z4: -51.15 | AA4: -61.142 | AB4: -67.171 | AC4: -68.819 | AD4: -66.083 | AE4: -59.818 | AF4: -51.755 | AG4: -43.966 | AH4: -38.018 | AI4: -34.209 | AJ4: -31.349 | AK4: -27.375 | AL4: -20.585 | AM4: -10.826 | AN4: 0.095 | AO4: 9.132 | AP4: 13.507 | AQ4: 12.218 | AR4: 6.757 | AS4: 0.695 | AT4: -1.74 | AU4: 2.441 | AV4: 13.394 | AW4: 27.987 | AX4: 40.963 | AY4: 47.367 | AZ4: 45.031 | BA4: 35.667 | BB4: 23.885 | BC4: 14.778 | BD4: 11.492 | BE4: 13.991 | BF4: 19.415 | BG4: 23.681 | BH4: 23.606 | BI4: 18.591 | BJ4: 10.955 | BK4: 4.57 | BL4: 2.552 | BM4: 5.538 | BN4: 11.66 | BO4: 18.019 | BP4: 22.371 | BQ4: 23.896 | BR4: 22.851 | BS4: 19.747 | BT4: 14.812 | BU4: 8.001 | BV4: -0.684 | BW4: -10.972 | BX4: -22.299 | BY4: -33.754 | BZ4: -43.854 | CA4: -50.426 | CB4: -51.124 | CC4: -44.656 | CD4: -32.046 | CE4: -16.875 | CF4: -4.039 | CG4: 2.519 | CH4: 1.866 | CI4: -3.318 | CJ4: -8.103 | CK4: -7.923 | CL4: -0.971 | CM4: 10.988 | CN4: 23.682 | CO4: 32.555 | CP4: 34.858 | CQ4: 30.603 | CR4: 22.079 | CS4: 12.37 | CT4: 3.763 | CU4: -3.123 | CV4: -9.121 | CW4: -15.536 | CX4: -23.13 | CY4: -31.664 | CZ4: -40.031 | DA4: -46.651 | DB4: -49.913 | DC4: -48.701 | DD4: -42.929 | DE4: -33.845 | DF4: -23.774 | DG4: -15.273 | DH4: -10.05 | DI4: -8.171 | DJ4: -8 | DK4: -6.977 | DL4: -2.94 | DM4: 4.667 | DN4: 14.451 | DO4: 23.926 | DP4: 31.054 | DQ4: 35.326 | DR4: 37.571 | DS4: 38.824 | DT4: 39.409 | DU4: 39.018 | DV4: 37.493 | DW4: 35.381 | DX4: 33.694 | DY4: 33.135 | DZ4: 33.549 | EA4: 34.123 | EB4: 34.102 | EC4: 33.275 | ED4: 31.801 | EE4: 29.694 | EF4: 26.655 | EG4: 22.401 | EH4: 16.935 | EI4: 10.3 | EJ4: 2.159 | EK4: -8.036 | EL4: -20.149 | EM4: -32.554 | EN4: -42.381 | EO4: -46.833 | EP4: -44.675 | EQ4: -36.847 | ER4: -25.904 | ES4: -14.879 | ET4: -6.362 | EU4: -2.122 | EV4: -2.981 | EW4: -8.599 | EX4: -17.269 | EY4: -26.248 | EZ4: -32.921 | FA4: -36.297 | FB4: -37.684 | FC4: -39.752 | FD4: -44.41 | FE4: -50.967 | FF4: -55.866 | FG4: -54.274 | FH4: -42.667 | FI4: -21.052 | FJ4: 6.389 | FK4: 32.719 | FL4: 51.171 | FM4: 58.086 | FN4: 54.232 | FO4: 43.831 | FP4: 32.108 | FQ4: 22.977 | FR4: 18.081 | FS4: 17.181 | FT4: 19.012 | FU4: 21.808 | FV4: 23.511 | FW4: 22.237 | FX4: 17.258 | FY4: 9.892 | FZ4: 3.244 | GA4: 0.495 | GB4: 2.787 | GC4: 8.383 | GD4: 13.915 | GE4: 16.765 | GF4: 16.655 | GG4: 15.241 | GH4: 14.19 | GI4: 13.42 | GJ4: 10.883 | GK4: 3.964 | GL4: -8.563 | GM4: -25.336 | GN4: -42.623 | GO4: -55.829 | GP4: -61.579 | GQ4: -59.401 | GR4: -52.074 | GS4: -44.197 | GT4: -39.527 | GU4: -38.646 | GV4: -38.63 | GW4: -35.109 | GX4: -25.398 | GY4: -10.543 | GZ4: 5.062 | HA4: 16.185 | HB4: 19.733 | HC4: 16.427 | HD4: 10.37 | HE4: 6.989 | HF4: 10.534 | HG4: 22.173 | HH4: 39.323 | HI4: 56.43 | HJ4: 67.158 | HK4: 67.309 | HL4: 57.056 | HM4: 40.979 | HN4: 25.579 | HO4: 15.706 | HP4: 12.23 | HQ4: 12.42 | HR4: 12.443 | HS4: 9.968 | HT4: 5.087 | HU4: -0.611 | HV4: -5.517 | HW4: -8.753 | HX4: -10.069 | HY4: -9.522 | HZ4: -7.405 | IA4: -4.214 | IB4: -0.415 | IC4: 3.85 | ID4: 8.778 | IE4: 14.544 | IF4: 20.889 | IG4: 26.984 | IH4: 31.656 | II4: 33.793 | IJ4: 32.663 | IK4: 28.017 | IL4: 20.059 | IM4: 9.407 | IN4: -2.925 | IO4: -15.672 | IP4: -27.576 | IQ4: -37.567 | IR4: -44.737 | IS4: -48.558 | IT4: -49.878 | IU4: -52.205 | IV4: -61.507 | IW4: -82.914 | IX4: -115.089 | IY4: -145.983 | IZ4: -154.662 | JA4: -121.271 | JB4: -41.492 | JC4: 64.112 | JD4: 156.992 | JE4: 206.18 | JF4: 211.22
A5: 4 | B5: 31 | C5: 1 | D5: 512 | E5: 0 | F5: 1691417479 | G5: 1 | H5: Alsanna | K5: ABR 3 left ear | M5: 4000 | N5: 60 | O5: 30 | P5: 90 | Q5: 5 | R5: 2 | S5: 40.96 | T5: 244 | U5: 0 | W5: 23.705 | X5: 46.035 | Y5: 57.304 | Z5: 57.239 | AA5: 49.58 | AB5: 39.736 | AC5: 32.267 | AD5: 29.245 | AE5: 29.951 | AF5: 31.836 | AG5: 32.273 | AH5: 30.124 | AI5: 26.216 | AJ5: 22.474 | AK5: 20.417 | AL5: 20.169 | AM5: 20.703 | AN5: 21.046 | AO5: 21.356 | AP5: 22.894 | AQ5: 26.786 | AR5: 32.57 | AS5: 37.794 | AT5: 39.142 | AU5: 34.412 | AV5: 24.087 | AW5: 11.499 | AX5: 1.41 | AY5: -2.27 | AZ5: 1.571 | BA5: 10.58 | BB5: 19.81 | BC5: 23.731 | BD5: 18.619 | BE5: 4.297 | BF5: -15.719 | BG5: -35.942 | BH5: -51.554 | BI5: -60.285 | BJ5: -62.532 | BK5: -60.108 | BL5: -54.897 | BM5: -48.308 | BN5: -41.45 | BO5: -35.438 | BP5: -31.376 | BQ5: -30.03 | BR5: -31.428 | BS5: -34.59 | BT5: -37.547 | BU5: -37.794 | BV5: -33.204 | BW5: -23.072 | BX5: -8.732 | BY5: 6.762 | BZ5: 19.877 | CA5: 28.184 | CB5: 31.41 | CC5: 31.369 | CD5: 30.793 | CE5: 31.724 | CF5: 34.412 | CG5: 37.471 | CH5: 39.203 | CI5: 39.159 | CJ5: 38.7 | CK5: 40.07 | CL5: 44.649 | CM5: 51.663 | CN5: 58.264 | CO5: 60.884 | CP5: 57.039 | CQ5: 46.607 | CR5: 31.963 | CS5: 16.882 | CT5: 4.78 | CU5: -2.78 | CV5: -6.527 | CW5: -8.759 | CX5: -12.012 | CY5: -17.896 | CZ5: -26.604 | DA5: -37.124 | DB5: -47.836 | DC5: -57.052 | DD5: -63.216 | DE5: -64.887 | DF5: -60.863 | DG5: -50.683 | DH5: -35.245 | DI5: -17.012 | DJ5: 0.474 | DK5: 13.591 | DL5: 19.696 | DM5: 17.892 | DN5: 9.271 | DO5: -3.454 | DP5: -16.81 | DQ5: -27.555 | DR5: -33.393 | DS5: -33.264 | DT5: -27.391 | DU5: -17.307 | DV5: -5.806 | DW5: 3.461 | DX5: 6.987 | DY5: 2.828 | DZ5: -8.151 | EA5: -22.045 | EB5: -33.155 | EC5: -36.369 | ED5: -29.521 | EE5: -14.46 | EF5: 3.773 | EG5: 19.176 | EH5: 27.242 | EI5: 26.506 | EJ5: 18.7 | EK5: 7.677 | EL5: -2.342 | EM5: -8.417 | EN5: -9.717 | EO5: -7.238 | EP5: -2.766 | EQ5: 2.194 | ER5: 6.976 | ES5: 11.572 | ET5: 15.983 | EU5: 19.62 | EV5: 21.328 | EW5: 20.12 | EX5: 16.039 | EY5: 10.433 | EZ5: 5.362 | FA5: 2.515 | FB5: 2.35 | FC5: 4.074 | FD5: 6.54 | FE5: 9.413 | FF5: 13.674 | FG5: 20.924 | FH5: 31.929 | FI5: 45.447 | FJ5: 58.268 | FK5: 66.58 | FL5: 67.94 | FM5: 62.661 | FN5: 53.709 | FO5: 45.065 | FP5: 39.569 | FQ5: 37.623 | FR5: 37.484 | FS5: 36.707 | FT5: 33.521 | FU5: 27.291 | FV5: 18.18 | FW5: 6.784 | FX5: -5.839 | FY5: -18.011 | FZ5: -27.758 | GA5: -33.719 | GB5: -36.12 | GC5: -37.015 | GD5: -39.402 | GE5: -45.544 | GF5: -55.405 | GG5: -66.245 | GH5: -73.836 | GI5: -74.676 | GJ5: -67.803 | GK5: -55.074 | GL5: -39.911 | GM5: -25.544 | GN5: -13.96 | GO5: -6.003 | GP5: -2.136 | GQ5: -2.889 | GR5: -8.509 | GS5: -18.166 | GT5: -29.551 | GU5: -39.256 | GV5: -43.708 | GW5: -40.228 | GX5: -27.984 | GY5: -8.674 | GZ5: 13.438 | HA5: 32.525 | HB5: 43.09 | HC5: 42.01 | HD5: 29.774 | HE5: 10.357 | HF5: -10.176 | HG5: -25.73 | HH5: -32.146 | HI5: -28.469 | HJ5: -17.196 | HK5: -3.416 | HL5: 6.996 | HM5: 9.606 | HN5: 3.204 | HO5: -9.703 | HP5: -23.944 | HQ5: -33.82 | HR5: -35.345 | HS5: -27.673 | HT5: -13.159 | HU5: 3.946 | HV5: 19.551 | HW5: 31.53 | HX5: 40.294 | HY5: 47.875 | HZ5: 56.233 | IA5: 65.926 | IB5: 75.885 | IC5: 84.093 | ID5: 88.518 | IE5: 87.832 | IF5: 81.856 | IG5: 71.825 | IH5: 60.237 | II5: 50.024 | IJ5: 43.124 | IK5: 39.229 | IL5: 35.638 | IM5: 28.538 | IN5: 15.054 | IO5: -5.168 | IP5: -29.69 | IQ5: -54.25 | IR5: -74.352 | IS5: -86.924 | IT5: -91.748 | IU5: -92.137 | IV5: -93.979 | IW5: -102.662 | IX5: -118.715 | IY5: -134.608 | IZ5: -135.746 | JA5: -107.219 | JB5: -44.15 | JC5: 40.981 | JD5: 122.276 | JE5: 177.909 | JF5: 206.489
A6: 5 | B6: 32 | C6: 1 | D6: 512 | E6: 0 | F6: 1691417504 | G6: 1 | H6: Alsanna | K6: ABR 3 left ear | M6: 4000 | N6: 50 | O6: 40 | P6: 90 | Q6: 5 | R6: 2 | S6: 40.96 | T6: 244 | U6: 0 | W6: 23.989 | X6: 29.527 | Y6: 38.546 | Z6: 50.702 | AA6: 64.033 | AB6: 75.451 | AC6: 82.046 | AD6: 82.542 | AE6: 77.922 | AF6: 70.753 | AG6: 63.741 | AH6: 58.556 | AI6: 55.582 | AJ6: 54.385 | AK6: 54.228 | AL6: 54.158 | AM6: 52.815 | AN6: 48.456 | AO6: 39.443 | AP6: 24.931 | AQ6: 5.272 | AR6: -18.127 | AS6: -43.286 | AT6: -68.085 | AU6: -90.417 | AV6: -108.146 | AW6: -119.268 | AX6: -122.568 | AY6: -118.553 | AZ6: -109.898 | BA6: -100.68 | BB6: -94.51 | BC6: -92.667 | BD6: -93.579 | BE6: -94.156 | BF6: -92.032 | BG6: -86.945 | BH6: -80.176 | BI6: -72.689 | BJ6: -63.75 | BK6: -51.368 | BL6: -34.226 | BM6: -13.51 | BN6: 6.934 | BO6: 22.453 | BP6: 30.311 | BQ6: 31.453 | BR6: 30.072 | BS6: 31.212 | BT6: 37.947 | BU6: 49.903 | BV6: 63.953 | BW6: 76.465 | BX6: 85.522 | BY6: 91.67 | BZ6: 96.812 | CA6: 102.17 | CB6: 106.876 | CC6: 108.304 | CD6: 104.017 | CE6: 93.898 | CF6: 80.777 | CG6: 68.955 | CH6: 61.666 | CI6: 59.293 | CJ6: 59.435 | CK6: 58.501 | CL6: 53.564 | CM6: 43.468 | CN6: 28.946 | CO6: 12.08 | CP6: -4.554 | CQ6: -18.769 | CR6: -29.453 | CS6: -36.813 | CT6: -42.134 | CU6: -47.201 | CV6: -53.635 | CW6: -62.265 | CX6: -72.57 | CY6: -82.45 | CZ6: -88.787 | DA6: -88.865 | DB6: -81.933 | DC6: -69.802 | DD6: -56.029 | DE6: -44.248 | DF6: -36.81 | DG6: -34.394 | DH6: -36.423 | DI6: -41.638 | DJ6: -48.383 | DK6: -54.599 | DL6: -57.895 | DM6: -55.984 | DN6: -47.531 | DO6: -33.01 | DP6: -15.005 | DQ6: 2.447 | DR6: 15.368 | DS6: 21.555 | DT6: 21.591 | DU6: 18.531 | DV6: 16.365 | DW6: 18.069 | DX6: 24.243 | DY6: 33.032 | DZ6: 41.287 | EA6: 46.299 | EB6: 47.047 | EC6: 44.27 | ED6: 39.457 | EE6: 33.611 | EF6: 26.753 | EG6: 18.455 | EH6: 8.878 | EI6: -0.665 | EJ6: -8.101 | EK6: -11.616 | EL6: -10.514 | EM6: -5.47 | EN6: 1.695 | EO6: 8.492 | EP6: 12.45 | EQ6: 11.989 | ER6: 7.077 | ES6: -0.764 | ET6: -9.172 | EU6: -15.918 | EV6: -19.601 | EW6: -19.828 | EX6: -16.977 | EY6: -11.788 | EZ6: -5.031 | FA6: 2.566 | FB6: 10.24 | FC6: 17.24 | FD6: 23.158 | FE6: 28.287 | FF6: 33.604 | FG6: 40.197 | FH6: 48.411 | FI6: 57.275 | FJ6: 64.627 | FK6: 67.983 | FL6: 65.737 | FM6: 58.054 | FN6: 46.986 | FO6: 35.725 | FP6: 27.326 | FQ6: 23.43 | FR6: 23.491 | FS6: 24.871 | FT6: 23.871 | FU6: 17.344 | FV6: 4.203 | FW6: -13.885 | FX6: -32.968 | FY6: -48.29 | FZ6: -56.178 | GA6: -55.532 | GB6: -48.211 | GC6: -38.154 | GD6: -29.688 | GE6: -25.948 | GF6: -28.109 | GG6: -35.55 | GH6: -46.472 | GI6: -58.467 | GJ6: -68.918 | GK6: -75.526 | GL6: -77.096 | GM6: -74.278 | GN6: -69.555 | GO6: -66.082 | GP6: -65.765 | GQ6: -67.734 | GR6: -68.326 | GS6: -62.818 | GT6: -48.003 | GU6: -24.174 | GV6: 4.556 | GW6: 31.708 | GX6: 50.975 | GY6: 58.792 | GZ6: 55.856 | HA6: 46.766 | HB6: 37.783 | HC6: 33.794 | HD6: 36.3 | HE6: 43.61 | HF6: 52.739 | HG6: 61.255 | HH6: 67.693 | HI6: 70.777 | HJ6: 68.879 | HK6: 60.709 | HL6: 46.772 | HM6: 30.071 | HN6: 15.052 | HO6: 5.223 | HP6: 1.089 | HQ6: -0.078 | HR6: -2.394 | HS6: -8.566 | HT6: -17.893 | HU6: -26.284 | HV6: -28.443 | HW6: -21.124 | HX6: -5.604 | HY6: 12.324 | HZ6: 25.125 | IA6: 27.544 | IB6: 19.441 | IC6: 5.697 | ID6: -6.659 | IE6: -12.268 | IF6: -9.972 | IG6: -2.894 | IH6: 3.625 | II6: 4.987 | IJ6: -0.219 | IK6: -9.413 | IL6: -17.335 | IM6: -18.899 | IN6: -12.021 | IO6: 1.229 | IP6: 15.873 | IQ6: 26.829 | IR6: 31.311 | IS6: 29.142 | IT6: 20.812 | IU6: 5.028 | IV6: -21.679 | IW6: -61.78 | IX6: -111.214 | IY6: -155.486 | IZ6: -172.135 | JA6: -141.44 | JB6: -61.311 | JC6: 43.782 | JD6: 131.267 | JE6: 168.33 | JF6: 155.951
A7: 6 | B7: 33 | C7: 1 | D7: 512 | E7: 0 | F7: 1691417529 | G7: 1 | H7: Alsanna | K7: ABR 3 left ear | M7: 4000 | N7: 40 | O7: 50 | P7: 90 | Q7: 5 | R7: 2 | S7: 40.96 | T7: 244 | U7: 0 | W7: -47.543 | X7: -92.78 | Y7: -124.232 | Z7: -137.977 | AA7: -136.22 | AB7: -125.01 | AC7: -110.9 | AD7: -98.393 | AE7: -89.092 | AF7: -82.368 | AG7: -76.725 | AH7: -70.988 | AI7: -64.891 | AJ7: -59.021 | AK7: -54.389 | AL7: -51.831 | AM7: -51.414 | AN7: -52.082 | AO7: -51.898 | AP7: -49.029 | AQ7: -42.988 | AR7: -35.196 | AS7: -28.25 | AT7: -24.251 | AU7: -23.289 | AV7: -23.114 | AW7: -20.264 | AX7: -11.974 | AY7: 2.217 | AZ7: 19.981 | BA7: 36.99 | BB7: 48.48 | BC7: 50.876 | BD7: 42.958 | BE7: 26.308 | BF7: 4.934 | BG7: -15.891 | BH7: -31.199 | BI7: -37.652 | BJ7: -34.114 | BK7: -21.435 | BL7: -1.784 | BM7: 22.08 | BN7: 47.406 | BO7: 71.815 | BP7: 93.412 | BQ7: 110.706 | BR7: 122.516 | BS7: 128.028 | BT7: 127.091 | BU7: 120.613 | BV7: 110.705 | BW7: 100.187 | BX7: 91.512 | BY7: 85.688 | BZ7: 81.924 | CA7: 78.244 | CB7: 72.648 | CC7: 64.109 | CD7: 52.931 | CE7: 40.399 | CF7: 27.912 | CG7: 16.023 | CH7: 3.928 | CI7: -10.109 | CJ7: -27.466 | CK7: -47.819 | CL7: -68.773 | CM7: -86.887 | CN7: -99.417 | CO7: -105.576 | CP7: -106.527 | CQ7: -104.32 | CR7: -100.609 | CS7: -96.046 | CT7: -90.589 | CU7: -84.288 | CV7: -77.774 | CW7: -72.016 | CX7: -67.683 | CY7: -64.835 | CZ7: -63.208 | DA7: -62.523 | DB7: -62.223 | DC7: -60.878 | DD7: -56.215 | DE7: -46.246 | DF7: -30.793 | DG7: -12.171 | DH7: 5.648 | DI7: 18.92 | DJ7: 25.928 | DK7: 27.731 | DL7: 27.57 | DM7: 29.325 | DN7: 35.717 | DO7: 47.022 | DP7: 60.859 | DQ7: 73.209 | DR7: 80.233 | DS7: 79.949 | DT7: 72.921 | DU7: 61.801 | DV7: 50.223 | DW7: 41.705 | DX7: 38.778 | DY7: 42.232 | DZ7: 50.513 | EA7: 59.777 | EB7: 65.073 | EC7: 62.474 | ED7: 51.002 | EE7: 33.03 | EF7: 12.782 | EG7: -6.07 | EH7: -21.991 | EI7: -35.303 | EJ7: -46.578 | EK7: -55.303 | EL7: -60.035 | EM7: -59.796 | EN7: -55.324 | EO7: -49.076 | EP7: -44.006 | EQ7: -42.084 | ER7: -43.455 | ES7: -46.478 | ET7: -48.392 | EU7: -46.308 | EV7: -38.252 | EW7: -23.881 | EX7: -4.505 | EY7: 17.588 | EZ7: 40.045 | FA7: 60.948 | FB7: 78.693 | FC7: 91.622 | FD7: 98.001 | FE7: 96.499 | FF7: 86.756 | FG7: 69.484 | FH7: 46.08 | FI7: 18.235 | FJ7: -11.951 | FK7: -41.489 | FL7: -66.379 | FM7: -82.474 | FN7: -87.173 | FO7: -80.944 | FP7: -67.585 | FQ7: -52.866 | FR7: -42.168 | FS7: -38.344 | FT7: -40.917 | FU7: -46.829 | FV7: -52.044 | FW7: -53.073 | FX7: -48.034 | FY7: -37.245 | FZ7: -23.16 | GA7: -9.329 | GB7: 1.389 | GC7: 8.301 | GD7: 12.973 | GE7: 17.889 | GF7: 24.736 | GG7: 33.466 | GH7: 42.547 | GI7: 49.958 | GJ7: 54.155 | GK7: 54.514 | GL7: 51.263 | GM7: 45.322 | GN7: 38.283 | GO7: 32.342 | GP7: 29.788 | GQ7: 31.992 | GR7: 38.495 | GS7: 46.86 | GT7: 53.539 | GU7: 55.28 | GV7: 50.358 | GW7: 39.085 | GX7: 23.468 | GY7: 6.274 | GZ7: -10.017 | HA7: -23.86 | HB7: -34.645 | HC7: -42.315 | HD7: -47.05 | HE7: -49.315 | HF7: -50.047 | HG7: -50.566 | HH7: -52.016 | HI7: -54.614 | HJ7: -57.269 | HK7: -58.008 | HL7: -55.067 | HM7: -47.994 | HN7: -38.058 | HO7: -27.694 | HP7: -19.343 | HQ7: -14.365 | HR7: -12.527 | HS7: -12.176 | HT7: -10.985 | HU7: -6.991 | HV7: 0.464 | HW7: 10.452 | HX7: 21.132 | HY7: 31.033 | HZ7: 40.04 | IA7: 49.224 | IB7: 59.528 | IC7: 70.325 | ID7: 79.201 | IE7: 83.43 | IF7: 82.083 | IG7: 76.918 | IH7: 71.129 | II7: 66.99 | IJ7: 64.349 | IK7: 61.049 | IL7: 54.566 | IM7: 43.376 | IN7: 27.267 | IO7: 6.966 | IP7: -16.157 | IQ7: -40.136 | IR7: -62.654 | IS7: -81.852 | IT7: -97.433 | IU7: -111.195 | IV7: -126.168 | IW7: -144.112 | IX7: -162.229 | IY7: -171.108 | IZ7: -156.512 | JA7: -106.421 | JB7: -21.221 | JC7: 79.797 | JD7: 164.418 | JE7: 208.309 | JF7: 213.233
A8: 7 | B8: 34 | C8: 1 | D8: 512 | E8: 0 | F8: 1691417554 | G8: 1 | H8: Alsanna | K8: ABR 3 left ear | M8: 4000 | N8: 30 | O8: 60 | P8: 90 | Q8: 5 | R8: 2 | S8: 40.96 | T8: 244 | U8: 0 | W8: 1.192 | X8: 41.079 | Y8: 66.386 | Z8: 76.341 | AA8: 76.437 | AB8: 74.418 | AC8: 76.038 | AD8: 82.821 | AE8: 92.286 | AF8: 99.737 | AG8: 100.426 | AH8: 91.386 | AI8: 72.733 | AJ8: 48.161 | AK8: 24.093 | AL8: 7.277 | AM8: 1.698 | AN8: 6.606 | AO8: 17.072 | AP8: 26.906 | AQ8: 32.037 | AR8: 32.13 | AS8: 29.619 | AT8: 27.259 | AU8: 26.131 | AV8: 25.335 | AW8: 23.123 | AX8: 18.338 | AY8: 11.171 | AZ8: 2.944 | BA8: -4.697 | BB8: -10.58 | BC8: -14.237 | BD8: -15.525 | BE8: -14.063 | BF8: -9.167 | BG8: -0.476 | BH8: 11.242 | BI8: 23.907 | BJ8: 34.884 | BK8: 42.168 | BL8: 45.104 | BM8: 44.102 | BN8: 39.703 | BO8: 31.862 | BP8: 20.104 | BQ8: 4.373 | BR8: -14.172 | BS8: -33.101 | BT8: -49.45 | BU8: -60.703 | BV8: -65.507 | BW8: -64.038 | BX8: -58.271 | BY8: -51.979 | BZ8: -49.84 | CA8: -55.367 | CB8: -68.577 | CC8: -85.261 | CD8: -98.875 | CE8: -104.066 | CF8: -99.334 | CG8: -86.982 | CH8: -70.752 | CI8: -53.329 | CJ8: -35.614 | CK8: -17.826 | CL8: -0.973 | CM8: 12.778 | CN8: 21.048 | CO8: 22.728 | CP8: 19.053 | CQ8: 13.672 | CR8: 11.468 | CS8: 16.36 | CT8: 29.06 | CU8: 46.197 | CV8: 61.747 | CW8: 70.185 | CX8: 69.511 | CY8: 62.171 | CZ8: 53.286 | DA8: 47.44 | DB8: 46.3 | DC8: 48.552 | DD8: 51.807 | DE8: 54.634 | DF8: 57.114 | DG8: 59.78 | DH8: 62.214 | DI8: 62.68 | DJ8: 59.181 | DK8: 51.045 | DL8: 39.746 | DM8: 28.298 | DN8: 19.65 | DO8: 15.136 | DP8: 13.831 | DQ8: 13.065 | DR8: 9.751 | DS8: 1.831 | DT8: -10.867 | DU8: -26.767 | DV8: -43.481 | DW8: -58.901 | DX8: -71.768 | DY8: -81.477 | DZ8: -87.521 | EA8: -89.256 | EB8: -86.29 | EC8: -79.083 | ED8: -68.979 | EE8: -57.47 | EF8: -45.327 | EG8: -32.458 | EH8: -18.688 | EI8: -4.758 | EJ8: 7.385 | EK8: 15.273 | EL8: 17.135 | EM8: 13.001 | EN8: 5.233 | EO8: -1.81 | EP8: -3.115 | EQ8: 4.974 | ER8: 22.907 | ES8: 47.258 | ET8: 71.722 | EU8: 89.376 | EV8: 95.128 | EW8: 87.392 | EX8: 68.422 | EY8: 43.318 | EZ8: 18.062 | FA8: -2.622 | FB8: -16.655 | FC8: -24.667 | FD8: -28.957 | FE8: -32.12 | FF8: -36.05 | FG8: -41.479 | FH8: -47.915 | FI8: -53.834 | FJ8: -57.162 | FK8: -55.993 | FL8: -49.401 | FM8: -38.057 | FN8: -24.359 | FO8: -11.813 | FP8: -3.735 | FQ8: -1.768 | FR8: -5.023 | FS8: -10.446 | FT8: -14.413 | FU8: -14.742 | FV8: -11.883 | FW8: -8.385 | FX8: -6.899 | FY8: -8.125 | FZ8: -10.289 | GA8: -10.508 | GB8: -6.884 | GC8: 0.29 | GD8: 8.897 | GE8: 16.327 | GF8: 20.749 | GG8: 21.776 | GH8: 20.531 | GI8: 19.184 | GJ8: 20.036 | GK8: 24.47 | GL8: 32.308 | GM8: 41.93 | GN8: 50.953 | GO8: 56.988 | GP8: 58.193 | GQ8: 53.724 | GR8: 44.212 | GS8: 31.995 | GT8: 20.645 | GU8: 13.692 | GV8: 13.143 | GW8: 18.659 | GX8: 27.786 | GY8: 36.949 | GZ8: 42.525 | HA8: 41.629 | HB8: 32.749 | HC8: 16.391 | HD8: -4.552 | HE8: -25.299 | HF8: -40.784 | HG8: -47.747 | HH8: -46.204 | HI8: -39.388 | HJ8: -32.057 | HK8: -28.045 | HL8: -28.467 | HM8: -31.633 | HN8: -34.601 | HO8: -35.216 | HP8: -33.34 | HQ8: -30.666 | HR8: -29.456 | HS8: -31.019 | HT8: -34.746 | HU8: -38.231 | HV8: -38.417 | HW8: -33.184 | HX8: -22.492 | HY8: -8.52 | HZ8: 5.165 | IA8: 14.926 | IB8: 18.363 | IC8: 15.231 | ID8: 7.589 | IE8: -1.004 | IF8: -6.995 | IG8: -8.294 | IH8: -4.947 | II8: 1.229 | IJ8: 7.728 | IK8: 12.605 | IL8: 15.284 | IM8: 16.493 | IN8: 17.388 | IO8: 18.57 | IP8: 19.773 | IQ8: 20.375 | IR8: 20.098 | IS8: 19.239 | IT8: 18.419 | IU8: 18.288 | IV8: 19.401 | IW8: 21.983 | IX8: 25.399 | IY8: 27.696 | IZ8: 25.932 | JA8: 17.533 | JB8: 2.147 | JC8: -17.287 | JD8: -35.569 | JE8: -48.611 | JF8: -56.326
A9: 8 | B9: 35 | C9: 1 | D9: 512 | E9: 0 | F9: 1691417579 | G9: 1 | H9: Alsanna | K9: ABR 3 left ear | M9: 4000 | N9: 20 | O9: 70 | P9: 90 | Q9: 5 | R9: 2 | S9: 40.96 | T9: 244 | U9: 0 | W9: 40.945 | X9: 115.548 | Y9: 164.403 | Z9: 183.882 | AA9: 180.874 | AB9: 166.981 | AC9: 152.381 | AD9: 142.675 | AE9: 139.098 | AF9: 140.382 | AG9: 144.481 | AH9: 149.435 | AI9: 153.552 | AJ9: 155.363 | AK9: 153.561 | AL9: 147.015 | AM9: 135.058 | AN9: 118.178 | AO9: 98.712 | AP9: 80.663 | AQ9: 68.064 | AR9: 62.601 | AS9: 62.119 | AT9: 61.364 | AU9: 54.743 | AV9: 39.408 | AW9: 16.719 | AX9: -8.776 | AY9: -32.079 | AZ9: -50.327 | BA9: -63.64 | BB9: -73.971 | BC9: -83.067 | BD9: -91.097 | BE9: -96.709 | BF9: -98.18 | BG9: -94.678 | BH9: -86.838 | BI9: -76.409 | BJ9: -65.347 | BK9: -54.964 | BL9: -45.686 | BM9: -37.541 | BN9: -30.999 | BO9: -27.423 | BP9: -28.558 | BQ9: -35.2 | BR9: -45.969 | BS9: -57.24 | BT9: -64.527 | BU9: -64.577 | BV9: -56.926 | BW9: -44.057 | BX9: -30.179 | BY9: -19.371 | BZ9: -14.06 | CA9: -14.389 | CB9: -18.505 | CC9: -23.41 | CD9: -26.016 | CE9: -24.136 | CF9: -17.241 | CG9: -6.744 | CH9: 4.43 | CI9: 13 | CJ9: 16.82 | CK9: 15.936 | CL9: 12.517 | CM9: 9.623 | CN9: 9.613 | CO9: 13.219 | CP9: 19.699 | CQ9: 27.58 | CR9: 35.29 | CS9: 41.401 | CT9: 44.804 | CU9: 45.161 | CV9: 43.466 | CW9: 41.999 | CX9: 43.217 | CY9: 48.11 | CZ9: 55.312 | DA9: 61.805 | DB9: 64.715 | DC9: 62.788 | DD9: 56.595 | DE9: 47.722 | DF9: 37.911 | DG9: 28.794 | DH9: 21.897 | DI9: 18.282 | DJ9: 17.767 | DK9: 18.568 | DL9: 18.15 | DM9: 15.005 | DN9: 9.96 | DO9: 5.721 | DP9: 4.821 | DQ9: 7.531 | DR9: 11.426 | DS9: 12.927 | DT9: 9.504 | DU9: 0.841 | DV9: -11.64 | DW9: -26.091 | DX9: -41.229 | DY9: -56.492 | DZ9: -71.64 | EA9: -86.26 | EB9: -99.414 | EC9: -109.543 | ED9: -114.77 | EE9: -113.604 | EF9: -105.781 | EG9: -92.771 | EH9: -77.606 | EI9: -63.987 | EJ9: -55.025 | EK9: -52.116 | EL9: -54.438 | EM9: -59.235 | EN9: -62.749 | EO9: -61.427 | EP9: -52.948 | EQ9: -36.825 | ER9: -14.568 | ES9: 10.51 | ET9: 33.991 | EU9: 51.723 | EV9: 61.583 | EW9: 64.73 | EX9: 65.251 | EY9: 67.923 | EZ9: 75.156 | FA9: 85.072 | FB9: 92.314 | FC9: 91.35 | FD9: 80.232 | FE9: 62.243 | FF9: 44.299 | FG9: 33.234 | FH9: 32.415 | FI9: 40.651 | FJ9: 53.53 | FK9: 65.85 | FL9: 73.575 | FM9: 74.659 | FN9: 69.08 | FO9: 58.633 | FP9: 46.526 | FQ9: 36.443 | FR9: 30.961 | FS9: 30.051 | FT9: 30.853 | FU9: 29.308 | FV9: 22.756 | FW9: 11.599 | FX9: -1.251 | FY9: -12.542 | FZ9: -20.563 | GA9: -25.33 | GB9: -27.4 | GC9: -26.821 | GD9: -23.353 | GE9: -17.594 | GF9: -11.667 | GG9: -8.44 | GH9: -9.689 | GI9: -14.725 | GJ9: -20.726 | GK9: -24.616 | GL9: -25.094 | GM9: -23.415 | GN9: -22.565 | GO9: -25.477 | GP9: -33.291 | GQ9: -44.555 | GR9: -55.87 | GS9: -63.763 | GT9: -66.722 | GU9: -66.007 | GV9: -64.622 | GW9: -65.169 | GX9: -68.124 | GY9: -71.687 | GZ9: -73.186 | HA9: -70.891 | HB9: -64.993 | HC9: -57.298 | HD9: -50.204 | HE9: -45.717 | HF9: -44.783 | HG9: -46.804 | HH9: -49.41 | HI9: -48.992 | HJ9: -42.187 | HK9: -27.628 | HL9: -6.784 | HM9: 16.708 | HN9: 38.758 | HO9: 56.512 | HP9: 69.26 | HQ9: 78.331 | HR9: 86.175 | HS9: 95.037 | HT9: 105.782 | HU9: 117.43 | HV9: 127.635 | HW9: 133.854 | HX9: 134.569 | HY9: 129.866 | HZ9: 120.984 | IA9: 109.166 | IB9: 94.723 | IC9: 77.121 | ID9: 56.018 | IE9: 32.238 | IF9: 7.755 | IG9: -15.241 | IH9: -35.275 | II9: -51.763 | IJ9: -64.613 | IK9: -73.85 | IL9: -79.588 | IM9: -82.085 | IN9: -81.667 | IO9: -78.66 | IP9: -73.529 | IQ9: -67.097 | IR9: -60.452 | IS9: -54.446 | IT9: -49.303 | IU9: -44.932 | IV9: -41.751 | IW9: -40.869 | IX9: -42.683 | IY9: -44.567 | IZ9: -40.087 | JA9: -21.923 | JB9: 12.095 | JC9: 54.171 | JD9: 88.719 | JE9: 103.153 | JF9: 97.857
A10: 9 | B10: 36 | C10: 1 | D10: 512 | E10: 0 | F10: 1691417604 | G10: 1 | H10: Alsanna | K10: ABR 3 left ear | M10: 8000 | N10: 90 | O10: 0 | P10: 90 | Q10: 5 | R10: 2 | S10: 40.96 | T10: 244 | U10: 0 | W10: 8.403 | X10: 32.215 | Y10: 43.427 | Z10: 44.233 | AA10: 40.486 | AB10: 37.322 | AC10: 36.266 | AD10: 35.268 | AE10: 30.862 | AF10: 20.638 | AG10: 4.702 | AH10: -14.26 | AI10: -32.051 | AJ10: -44.572 | AK10: -49.312 | AL10: -46.181 | AM10: -37.408 | AN10: -26.623 | AO10: -17.506 | AP10: -12.547 | AQ10: -12.263 | AR10: -15.015 | AS10: -17.471 | AT10: -15.757 | AU10: -7.099 | AV10: 8.71 | AW10: 28.876 | AX10: 48.663 | AY10: 63.488 | AZ10: 70.858 | BA10: 71.11 | BB10: 66.722 | BC10: 60.915 | BD10: 56.442 | BE10: 54.998 | BF10: 57.077 | BG10: 61.971 | BH10: 67.847 | BI10: 72.027 | BJ10: 71.597 | BK10: 64.346 | BL10: 49.769 | BM10: 29.695 | BN10: 8.021 | BO10: -10.53 | BP10: -22.203 | BQ10: -25.759 | BR10: -23.045 | BS10: -18.266 | BT10: -16.167 | BU10: -19.895 | BV10: -29.613 | BW10: -42.551 | BX10: -54.366 | BY10: -60.978 | BZ10: -60.13 | CA10: -52.32 | CB10: -40.899 | CC10: -31.063 | CD10: -27.753 | CE10: -33.235 | CF10: -45.625 | CG10: -59.356 | CH10: -67.639 | CI10: -65.812 | CJ10: -53.833 | CK10: -36.462 | CL10: -20.832 | CM10: -12.632 | CN10: -13.034 | CO10: -18.137 | CP10: -21.253 | CQ10: -16.672 | CR10: -2.716 | CS10: 17.693 | CT10: 39.213 | CU10: 57.597 | CV10: 72.239 | CW10: 86.064 | CX10: 102.869 | CY10: 123.942 | CZ10: 146.175 | DA10: 162.865 | DB10: 166.66 | DC10: 152.973 | DD10: 122.029 | DE10: 78.664 | DF10: 30.332 | DG10: -15.273 | DH10: -51.792 | DI10: -74.81 | DJ10: -82.16 | DK10: -74.432 | DL10: -55.339 | DM10: -31.147 | DN10: -8.895 | DO10: 5.922 | DP10: 11.005 | DQ10: 7.391 | DR10: -1.842 | DS10: -13.514 | DT10: -25.858 | DU10: -38.889 | DV10: -53.599 | DW10: -70.597 | DX10: -89.098 | DY10: -106.841 | DZ10: -120.893 | EA10: -128.832 | EB10: -129.664 | EC10: -124.093 | ED10: -114.062 | EE10: -101.874 | EF10: -89.323 | EG10: -77.248 | EH10: -65.634 | EI10: -54.119 | EJ10: -42.588 | EK10: -31.453 | EL10: -21.403 | EM10: -12.797 | EN10: -5.233 | EO10: 2.327 | EP10: 11.027 | EQ10: 21.774 | ER10: 35.366 | ES10: 52.769 | ET10: 74.864 | EU10: 101.506 | EV10: 130.497 | EW10: 157.345 | EX10: 176.243 | EY10: 181.939 | EZ10: 171.685 | FA10: 146.347 | FB10: 110.153 | FC10: 69.214 | FD10: 29.525 | FE10: -4.667 | FF10: -31.508 | FG10: -51.18 | FH10: -64.994 | FI10: -74.564 | FJ10: -81.389 | FK10: -86.711 | FL10: -91.334 | FM10: -95.26 | FN10: -97.386 | FO10: -95.678 | FP10: -87.995 | FQ10: -73.235 | FR10: -52.118 | FS10: -27.1 | FT10: -1.47 | FU10: 21.871 | FV10: 41.37 | FW10: 57.194 | FX10: 70.894 | FY10: 84.459 | FZ10: 99.11 | GA10: 114.38 | GB10: 128.026 | GC10: 136.908 | GD10: 138.495 | GE10: 132.297 | GF10: 120.444 | GG10: 106.94 | GH10: 95.839 | GI10: 89.352 | GJ10: 86.97 | GK10: 85.955 | GL10: 82.626 | GM10: 73.601 | GN10: 56.727 | GO10: 31.821 | GP10: 1.194 | GQ10: -30.634 | GR10: -58.509 | GS10: -79.007 | GT10: -92.079 | GU10: -100.682 | GV10: -108.577 | GW10: -117.88 | GX10: -128.006 | GY10: -136.434 | GZ10: -140.413 | HA10: -138.433 | HB10: -130.804 | HC10: -119.414 | HD10: -106.989 | HE10: -96.103 | HF10: -88.085 | HG10: -82.233 | HH10: -75.97 | HI10: -66.246 | HJ10: -51.5 | HK10: -32.854 | HL10: -13.67 | HM10: 2.212 | HN10: 12.287 | HO10: 16.154 | HP10: 15.078 | HQ10: 11.019 | HR10: 5.882 | HS10: 1.182 | HT10: -2.115 | HU10: -3.753 | HV10: -4.132 | HW10: -3.796 | HX10: -2.625 | HY10: 0.594 | HZ10: 7.586 | IA10: 19.14 | IB10: 33.86 | IC10: 48.255 | ID10: 58.349 | IE10: 61.754 | IF10: 58.862 | IG10: 52.538 | IH10: 46.756 | II10: 44.97 | IJ10: 48.813 | IK10: 57.422 | IL10: 67.614 | IM10: 75.01 | IN10: 75.746 | IO10: 67.979 | IP10: 52.495 | IQ10: 32.185 | IR10: 10.897 | IS10: -7.582 | IT10: -19.883 | IU10: -22.981 | IV10: -14.538 | IW10: 5.646 | IX10: 33.355 | IY10: 58.585 | IZ10: 67.429 | JA10: 48.315 | JB10: 0.402 | JC10: -61.642 | JD10: -112.977 | JE10: -134.738 | JF10: -127.473
A11: 10 | B11: 37 | C11: 1 | D11: 512 | E11: 0 | F11: 1691417628 | G11: 1 | H11: Alsanna | K11: ABR 3 left ear | M11: 8000 | N11: 80 | O11: 10 | P11: 90 | Q11: 5 | R11: 2 | S11: 40.96 | T11: 244 | U11: 0 | W11: -2.911 | X11: -4.01 | Y11: 1.328 | Z11: 8.611 | AA11: 12.386 | AB11: 9.622 | AC11: 1.324 | AD11: -8.599 | AE11: -16.214 | AF11: -20.06 | AG11: -21.69 | AH11: -24.217 | AI11: -30.151 | AJ11: -39.92 | AK11: -51.702 | AL11: -62.353 | AM11: -68.863 | AN11: -69.689 | AO11: -65.383 | AP11: -58.192 | AQ11: -50.803 | AR11: -44.934 | AS11: -40.652 | AT11: -36.824 | AU11: -32.244 | AV11: -26.482 | AW11: -19.835 | AX11: -12.734 | AY11: -5.368 | AZ11: 2.144 | BA11: 9.525 | BB11: 16.528 | BC11: 23.301 | BD11: 30.339 | BE11: 37.857 | BF11: 45.17 | BG11: 50.608 | BH11: 52.043 | BI11: 47.692 | BJ11: 36.948 | BK11: 21.111 | BL11: 3.699 | BM11: -10.174 | BN11: -15.568 | BO11: -10.053 | BP11: 4.774 | BQ11: 23.826 | BR11: 41.12 | BS11: 52.858 | BT11: 58.955 | BU11: 62.033 | BV11: 64.76 | BW11: 67.546 | BX11: 68.162 | BY11: 63.377 | BZ11: 51.312 | CA11: 32.933 | CB11: 11.887 | CC11: -7.062 | CD11: -20.067 | CE11: -25.677 | CF11: -25.167 | CG11: -21.694 | CH11: -18.79 | CI11: -18.924 | CJ11: -22.762 | CK11: -29.369 | CL11: -37.079 | CM11: -44.407 | CN11: -50.406 | CO11: -54.367 | CP11: -55.371 | CQ11: -52.33 | CR11: -44.641 | CS11: -32.908 | CT11: -18.963 | CU11: -5.105 | CV11: 6.822 | CW11: 15.738 | CX11: 20.929 | CY11: 21.581 | CZ11: 16.975 | DA11: 7.377 | DB11: -5.064 | DC11: -16.336 | DD11: -21.937 | DE11: -19.039 | DF11: -8.145 | DG11: 6.958 | DH11: 21.083 | DI11: 30.222 | DJ11: 33.219 | DK11: 31.547 | DL11: 27.456 | DM11: 21.906 | DN11: 13.878 | DO11: 1.676 | DP11: -14.769 | DQ11: -32.479 | DR11: -46.195 | DS11: -51.056 | DT11: -45.462 | DU11: -32.155 | DV11: -16.707 | DW11: -4.426 | DX11: 2.155 | DY11: 3.593 | DZ11: 1.867 | EA11: -1.578 | EB11: -6.472 | EC11: -12.913 | ED11: -20.258 | EE11: -26.918 | EF11: -31.271 | EG11: -32.872 | EH11: -32.846 | EI11: -33.013 | EJ11: -34.314 | EK11: -35.749 | EL11: -34.787 | EM11: -29.11 | EN11: -18.489 | EO11: -5.354 | EP11: 6.494 | EQ11: 14.203 | ER11: 17.649 | ES11: 19.449 | ET11: 23.169 | EU11: 30.835 | EV11: 41.281 | EW11: 50.475 | EX11: 53.784 | EY11: 48.901 | EZ11: 37.555 | FA11: 24.913 | FB11: 17.131 | FC11: 18.599 | FD11: 30.329 | FE11: 49.901 | FF11: 72.61 | FG11: 93.154 | FH11: 107.272 | FI11: 112.79 | FJ11: 109.678 | FK11: 99.3 | FL11: 83.563 | FM11: 64.546 | FN11: 44.523 | FO11: 25.804 | FP11: 10.074 | FQ11: -2.333 | FR11: -12.578 | FS11: -22.573 | FT11: -33.799 | FU11: -46.391 | FV11: -58.992 | FW11: -69.408 | FX11: -75.77 | FY11: -77.654 | FZ11: -76.501 | GA11: -74.971 | GB11: -75.542 | GC11: -79.236 | GD11: -85.15 | GE11: -90.839 | GF11: -93.111 | GG11: -88.896 | GH11: -76.092 | GI11: -54.302 | GJ11: -25.229 | GK11: 7.445 | GL11: 38.639 | GM11: 62.845 | GN11: 75.437 | GO11: 74.141 | GP11: 60.04 | GQ11: 37.461 | GR11: 12.576 | GS11: -8.682 | GT11: -22.478 | GU11: -27.925 | GV11: -26.656 | GW11: -21.402 | GX11: -14.434 | GY11: -6.752 | GZ11: 1.58 | HA11: 10.419 | HB11: 18.696 | HC11: 24.361 | HD11: 25.194 | HE11: 20.029 | HF11: 9.715 | HG11: -2.856 | HH11: -13.843 | HI11: -20.228 | HJ11: -21.227 | HK11: -18.432 | HL11: -14.53 | HM11: -11.422 | HN11: -8.969 | HO11: -5.256 | HP11: 1.757 | HQ11: 12.215 | HR11: 23.292 | HS11: 29.837 | HT11: 26.619 | HU11: 11.229 | HV11: -13.785 | HW11: -40.895 | HX11: -60.145 | HY11: -63.342 | HZ11: -47.812 | IA11: -17.68 | IB11: 18.058 | IC11: 49.598 | ID11: 70.31 | IE11: 78.599 | IF11: 76.986 | IG11: 69.484 | IH11: 59.178 | II11: 47.449 | IJ11: 34.752 | IK11: 21.761 | IL11: 9.712 | IM11: -0.146 | IN11: -7.201 | IO11: -11.481 | IP11: -13.114 | IQ11: -11.934 | IR11: -7.775 | IS11: -1.324 | IT11: 5.057 | IU11: 7.294 | IV11: 0.835 | IW11: -16.893 | IX11: -43.818 | IY11: -72.061 | IZ11: -89.789 | JA11: -86.225 | JB11: -57.965 | JC11: -12.743 | JD11: 33.488 | JE11: 67.084 | JF11: 86.386
A12: 11 | B12: 38 | C12: 1 | D12: 512 | E12: 0 | F12: 1691417653 | G12: 1 | H12: Alsanna | K12: ABR 3 left ear | M12: 8000 | N12: 70 | O12: 20 | P12: 90 | Q12: 5 | R12: 2 | S12: 40.96 | T12: 244 | U12: 0 | W12: -34.711 | X12: -99.622 | Y12: -135.796 | Z12: -141.752 | AA12: -127.752 | AB12: -108.673 | AC12: -96.021 | AD12: -93.567 | AE12: -97.997 | AF12: -102.965 | AG12: -103.489 | AH12: -98.285 | AI12: -89.373 | AJ12: -80.034 | AK12: -72.699 | AL12: -67.876 | AM12: -64.34 | AN12: -60.271 | AO12: -54.677 | AP12: -48.331 | AQ12: -43.577 | AR12: -43.067 | AS12: -48.219 | AT12: -58.315 | AU12: -70.632 | AV12: -81.312 | AW12: -86.581 | AX12: -83.992 | AY12: -73.374 | AZ12: -56.942 | BA12: -38.229 | BB12: -20.271 | BC12: -4.184 | BD12: 10.836 | BE12: 26.134 | BF12: 41.953 | BG12: 56.795 | BH12: 68.224 | BI12: 74.367 | BJ12: 74.952 | BK12: 71.212 | BL12: 65.016 | BM12: 58.136 | BN12: 52.158 | BO12: 48.639 | BP12: 48.758 | BQ12: 52.393 | BR12: 57.505 | BS12: 60.789 | BT12: 59.517 | BU12: 53.382 | BV12: 44.989 | BW12: 38.538 | BX12: 37.485 | BY12: 42.617 | BZ12: 51.71 | CA12: 60.888 | CB12: 66.664 | CC12: 67.318 | CD12: 62.965 | CE12: 54.737 | CF12: 43.898 | CG12: 31.443 | CH12: 18.158 | CI12: 4.842 | CJ12: -7.595 | CK12: -18.268 | CL12: -26.633 | CM12: -32.84 | CN12: -37.861 | CO12: -43.173 | CP12: -50.004 | CQ12: -58.557 | CR12: -67.714 | CS12: -75.493 | CT12: -80.06 | CU12: -80.729 | CV12: -78.361 | CW12: -74.903 | CX12: -72.311 | CY12: -71.395 | CZ12: -71.137 | DA12: -68.948 | DB12: -61.955 | DC12: -48.86 | DD12: -31.27 | DE12: -13.436 | DF12: -0.185 | DG12: 5.824 | DH12: 5.627 | DI12: 3.039 | DJ12: 1.853 | DK12: 3.219 | DL12: 5.239 | DM12: 5.059 | DN12: 1.729 | DO12: -2.484 | DP12: -3.375 | DQ12: 2.366 | DR12: 14.838 | DS12: 30.663 | DT12: 44.766 | DU12: 53.02 | DV12: 54.274 | DW12: 50.781 | DX12: 46.886 | DY12: 46.694 | DZ12: 51.969 | EA12: 61.358 | EB12: 71.23 | EC12: 77.485 | ED12: 77.32 | EE12: 70.209 | EF12: 57.964 | EG12: 44.055 | EH12: 32.399 | EI12: 25.802 | EJ12: 24.526 | EK12: 25.786 | EL12: 24.754 | EM12: 16.875 | EN12: 0.339 | EO12: -22.7 | EP12: -46.936 | EQ12: -66.336 | ER12: -76.807 | ES12: -77.63 | ET12: -71.108 | EU12: -60.961 | EV12: -50.517 | EW12: -41.597 | EX12: -34.374 | EY12: -28.073 | EZ12: -22.061 | FA12: -16.659 | FB12: -13.071 | FC12: -12.377 | FD12: -14.373 | FE12: -17.294 | FF12: -18.868 | FG12: -18.02 | FH12: -15.889 | FI12: -15.158 | FJ12: -17.896 | FK12: -23.432 | FL12: -28.027 | FM12: -26.928 | FN12: -17.482 | FO12: -1.044 | FP12: 17.629 | FQ12: 32.92 | FR12: 41.001 | FS12: 41.085 | FT12: 35.028 | FU12: 26.01 | FV12: 17.161 | FW12: 10.619 | FX12: 7.085 | FY12: 5.876 | FZ12: 5.444 | GA12: 4.278 | GB12: 1.826 | GC12: -1.116 | GD12: -2.929 | GE12: -2.38 | GF12: 0.352 | GG12: 3.777 | GH12: 6.37 | GI12: 7.993 | GJ12: 10.197 | GK12: 15.094 | GL12: 23.723 | GM12: 35.15 | GN12: 46.861 | GO12: 56.015 | GP12: 60.722 | GQ12: 60.665 | GR12: 56.871 | GS12: 50.859 | GT12: 43.675 | GU12: 35.379 | GV12: 25.286 | GW12: 12.792 | GX12: -1.79 | GY12: -16.967 | GZ12: -30.545 | HA12: -40.505 | HB12: -45.735 | HC12: -46.231 | HD12: -42.797 | HE12: -36.607 | HF12: -28.991 | HG12: -21.438 | HH12: -15.514 | HI12: -12.436 | HJ12: -12.474 | HK12: -14.695 | HL12: -17.318 | HM12: -18.541 | HN12: -17.402 | HO12: -14.296 | HP12: -11 | HQ12: -10.113 | HR12: -13.95 | HS12: -23.222 | HT12: -36.209 | HU12: -49.166 | HV12: -58.017 | HW12: -60.436 | HX12: -56.932 | HY12: -50.211 | HZ12: -43.403 | IA12: -38.482 | IB12: -35.812 | IC12: -34.657 | ID12: -33.876 | IE12: -32.302 | IF12: -28.92 | IG12: -23.05 | IH12: -14.441 | II12: -3.009 | IJ12: 11.513 | IK12: 29.387 | IL12: 49.904 | IM12: 70.399 | IN12: 86.437 | IO12: 93.603 | IP12: 89.928 | IQ12: 77.282 | IR12: 60.741 | IS12: 46.453 | IT12: 39.46 | IU12: 42.543 | IV12: 55.919 | IW12: 76.914 | IX12: 99.268 | IY12: 113.007 | IZ12: 106.473 | JA12: 71.145 | JB12: 7.701 | JC12: -70.703 | JD12: -142.733 | JE12: -191.941 | JF12: -218.178
